<?xml version='1.0' encoding='utf-8'?>
<robot name="arm3">
    <link name="base_link">
        <inertial>
            <origin xyz="-1.188415750328633e-09 -0.020862080792945627 0.02351089822104169" rpy="0.0 0.0 0.0" />
            <mass value="0.8649605268138625" />
            <inertia ixx="0.0005091080176490385" iyy="0.00040051606955903633" izz="0.000456781148628419" ixy="2.017447833990726e-11" iyz="6.001050632423394e-05" ixz="1.2800998119586669e-11" />
        </inertial>
        <visual name="base_link_visual">
            <origin xyz="0.0 0.0 0.0" rpy="0.0 0.0 0.0" />
            <geometry>
                <mesh filename="package://arm3_description/meshes/base_link.stl" scale="0.001 0.001 0.001" />
            </geometry>
        </visual>
        <collision name="base_link_collision">
            <origin xyz="0.0 0.0 0.0" rpy="0.0 0.0 0.0" />
            <geometry>
                <mesh filename="package://arm3_description/meshes/base_link.stl" scale="0.001 0.001 0.001" />
            </geometry>
        </collision>
    </link>
    <link name="arm_1">
        <inertial>
            <origin xyz="0.10650064034424997 -5.514573064857586e-10 -0.014859090607788348" rpy="0.0 -0.0 0.0" />
            <mass value="1.8640074270642077" />
            <inertia ixx="0.0012293916356250095" iyy="0.007030587931090102" izz="0.006618762705733333" ixy="9.733320139454493e-11" iyz="1.4003596025824482e-11" ixz="0.0010796405966336652" />
        </inertial>
        <visual name="arm_1_visual">
            <origin xyz="0.072 -0.045 0.0030000021411000083" rpy="1.5707963267948963 4.5261550790144846e-79 -2.2315667455012782e-110" />
            <geometry>
                <mesh filename="package://arm3_description/meshes/arm_1.stl" scale="0.001 0.001 0.001" />
            </geometry>
        </visual>
        <collision name="arm_1_collision">
            <origin xyz="0.072 -0.045 0.0030000021411000083" rpy="1.5707963267948963 4.5261550790144846e-79 -2.2315667455012782e-110" />
            <geometry>
                <mesh filename="package://arm3_description/meshes/arm_1.stl" scale="0.001 0.001 0.001" />
            </geometry>
        </collision>
    </link>
    <link name="arm_2">
        <inertial>
            <origin xyz="9.298725345274761e-10 -0.046322761859584 -0.01124850249317479" rpy="0.0 -0.0 0.0" />
            <mass value="1.1054515445122186" />
            <inertia ixx="0.0011269854729143332" iyy="0.0006146812341975352" izz="0.0009027924480591032" ixy="6.493354465231249e-12" iyz="-0.00029226251125904893" ixz="3.3793059496523004e-12" />
        </inertial>
        <visual name="arm_2_visual">
            <origin xyz="0.013500000000000014 -0.05849999999999998 0.003000004282200013" rpy="1.5707963267948963 -0.0 2.698802673467014e-79" />
            <geometry>
                <mesh filename="package://arm3_description/meshes/arm_2.stl" scale="0.001 0.001 0.001" />
            </geometry>
        </visual>
        <collision name="arm_2_collision">
            <origin xyz="0.013500000000000014 -0.05849999999999998 0.003000004282200013" rpy="1.5707963267948963 -0.0 2.698802673467014e-79" />
            <geometry>
                <mesh filename="package://arm3_description/meshes/arm_2.stl" scale="0.001 0.001 0.001" />
            </geometry>
        </collision>
    </link>
    <link name="arm_3">
        <inertial>
            <origin xyz="-3.801403636316536e-15 0.01766179279414297 0.028362432726066623" rpy="0.0 -0.0 0.0" />
            <mass value="0.3866919911236247" />
            <inertia ixx="0.00022345752781510568" iyy="0.00020435292015233072" izz="0.00014285677267166473" ixy="3.0040753277961116e-11" iyz="-6.055343015939629e-05" ixz="3.004076674917311e-11" />
        </inertial>
        <visual name="arm_3_visual">
            <origin xyz="7.105427357601002e-17 4.282200001259895e-09 0.0030000021410999623" rpy="-1.9890203340171088e-16 -0.0 5.618011625630638e-95" />
            <geometry>
                <mesh filename="package://arm3_description/meshes/arm_3.stl" scale="0.001 0.001 0.001" />
            </geometry>
        </visual>
        <collision name="arm_3_collision">
            <origin xyz="7.105427357601002e-17 4.282200001259895e-09 0.0030000021410999623" rpy="-1.9890203340171088e-16 -0.0 5.618011625630638e-95" />
            <geometry>
                <mesh filename="package://arm3_description/meshes/arm_3.stl" scale="0.001 0.001 0.001" />
            </geometry>
        </collision>
    </link>
    <link name="arm_4">
        <inertial>
            <origin xyz="-0.08599999999999698 2.1645027814543027e-09 0.02008578479393376" rpy="0.0 -0.0 0.0" />
            <mass value="2.371653909040455" />
            <inertia ixx="0.0012533831266328815" iyy="0.01074299476657482" izz="0.010481174641859214" ixy="-1.767307966638043e-10" iyz="-3.4019488615030274e-13" ixz="1.4635075977272978e-16" />
        </inertial>
        <visual name="arm_4_visual">
            <origin xyz="-0.09999999999999994 0.04500000214109992 -4.282200002092563e-09" rpy="-1.5707963267948966 -0.0 0.0" />
            <geometry>
                <mesh filename="package://arm3_description/meshes/arm_4.stl" scale="0.001 0.001 0.001" />
            </geometry>
        </visual>
        <collision name="arm_4_collision">
            <origin xyz="-0.09999999999999994 0.04500000214109992 -4.282200002092563e-09" rpy="-1.5707963267948966 -0.0 0.0" />
            <geometry>
                <mesh filename="package://arm3_description/meshes/arm_4.stl" scale="0.001 0.001 0.001" />
            </geometry>
        </collision>
    </link>
    <link name="arm_5">
        <inertial>
            <origin xyz="2.7011624616588083e-17 0.03604999785890012 0.01051589269916724" rpy="0.0 -0.0 0.0" />
            <mass value="0.5465524334585093" />
            <inertia ixx="0.0005395879319698271" iyy="9.64355550217386e-05" izz="0.0006159254529286146" ixy="-6.008158682764333e-11" iyz="2.0991072260237423e-19" ixz="-8.552667084117707e-22" />
        </inertial>
        <visual name="arm_5_visual">
            <origin xyz="0.024999999950109417 0.012999997809009437 0.003000004282200003" rpy="1.5707963267948966 9.363352709384395e-97 -4.2168791772922093e-81" />
            <geometry>
                <mesh filename="package://arm3_description/meshes/arm_5.stl" scale="0.001 0.001 0.001" />
            </geometry>
        </visual>
        <collision name="arm_5_collision">
            <origin xyz="0.024999999950109417 0.012999997809009437 0.003000004282200003" rpy="1.5707963267948966 9.363352709384395e-97 -4.2168791772922093e-81" />
            <geometry>
                <mesh filename="package://arm3_description/meshes/arm_5.stl" scale="0.001 0.001 0.001" />
            </geometry>
        </collision>
    </link>
    <link name="arm_6">
        <inertial>
            <origin xyz="0.03770065749058546 9.494893227213196e-10 0.01998358486384085" rpy="0.0 -0.0 0.0" />
            <mass value="1.7253109869141712" />
            <inertia ixx="0.0007363358667145381" iyy="0.001899600097244089" izz="0.001765437785906484" ixy="1.1718103917757183e-11" iyz="-2.6388872857718845e-11" ixz="0.0001241716581803469" />
        </inertial>
        <visual name="arm_6_visual">
            <origin xyz="0.06350000000000003 0.06876191428219997 0.013761907858900017" rpy="-1.5707963267948968 -0.0 0.0" />
            <geometry>
                <mesh filename="package://arm3_description/meshes/arm_6.stl" scale="0.001 0.001 0.001" />
            </geometry>
        </visual>
        <collision name="arm_6_collision">
            <origin xyz="0.06350000000000003 0.06876191428219997 0.013761907858900017" rpy="-1.5707963267948968 -0.0 0.0" />
            <geometry>
                <mesh filename="package://arm3_description/meshes/arm_6.stl" scale="0.001 0.001 0.001" />
            </geometry>
        </collision>
    </link>
    <joint name="servo_1" type="revolute">
        <origin xyz="0.0 -0.0007380900000000001 0.036000000000000004" rpy="-1.5707963267948966 -0.0 0.0" />
        <parent link="base_link" />
        <child link="arm_1" />
        <axis xyz="0.0 4.9303806576313216e-32 1.0" />
        <limit lower="-3.141593" upper="0.0" effort="100" velocity="5.0" />
    </joint>
    <joint name="servo_2" type="revolute">
        <origin xyz="0.172 0.0 -0.0007380900000000001" rpy="-4.9303806576313216e-32 -0.0 0.0" />
        <parent link="arm_1" />
        <child link="arm_2" />
        <axis xyz="0.0 0.0 1.0" />
        <limit lower="0.0" upper="3.141593" effort="100" velocity="5.0" />
    </joint>
    <joint name="servo_3" type="revolute">
        <origin xyz="0.0 -0.08236191 -0.014499999999999999" rpy="1.5707963267948966 -0.0 0.0" />
        <parent link="arm_2" />
        <child link="arm_3" />
        <axis xyz="0.0 0.0 1.0" />
        <limit lower="-1.570796" upper="1.570796" effort="100" velocity="5.0" />
    </joint>
    <joint name="servo_4" type="revolute">
        <origin xyz="0.0 0.014499999999999999 0.04650000000000002" rpy="1.5707963267948966 -0.0 0.0" />
        <parent link="arm_3" />
        <child link="arm_4" />
        <axis xyz="0.0 -1.5407439555097887e-33 1.0" />
        <limit lower="-3.141593" upper="0.0" effort="100" velocity="5.0" />
    </joint>
    <joint name="servo_5" type="revolute">
        <origin xyz="-0.172 0.0 0.0" rpy="3.141592653589793 -0.0 0.0" />
        <parent link="arm_4" />
        <child link="arm_5" />
        <axis xyz="0.0 -2.2204460492503126e-16 1.0" />
        <limit lower="0.0" upper="3.141593" effort="100" velocity="5.0" />
    </joint>
    <joint name="servo_6" type="revolute">
        <origin xyz="0.0 0.07210000000000001 1.609823385706477e-17" rpy="-3.141592653589793 -0.0 0.0" />
        <parent link="arm_5" />
        <child link="arm_6" />
        <axis xyz="0.0 1.5407439555097887e-33 1.0" />
        <limit lower="-3.141593" upper="0.0" effort="100" velocity="5.0" />
    </joint>
</robot>